2025-06-01 01:47:56,138 - django.utils.autoreload - INFO - C:\Users\puttu\OneDrive\Desktop\Vardaan\GRC_risk_module\backend\grc\views.py changed, reloading.
2025-06-01 01:48:25,011 - django.utils.autoreload - INFO - C:\Users\puttu\OneDrive\Desktop\Vardaan\GRC_risk_module\backend\grc\views.py changed, reloading.
2025-06-01 01:48:55,941 - django.utils.autoreload - INFO - C:\Users\puttu\OneDrive\Desktop\Vardaan\GRC_risk_module\backend\grc\views.py changed, reloading.
2025-06-01 01:49:04,254 - django.utils.autoreload - INFO - C:\Users\puttu\OneDrive\Desktop\Vardaan\GRC_risk_module\backend\grc\views.py changed, reloading.
2025-06-01 01:49:18,451 - django.utils.autoreload - INFO - C:\Users\puttu\OneDrive\Desktop\Vardaan\GRC_risk_module\backend\grc\views.py changed, reloading.
2025-06-01 02:25:03,057 - django.utils.autoreload - INFO - C:\Users\puttu\OneDrive\Desktop\Vardaan\GRC_risk_module\backend\grc\views.py changed, reloading.
2025-06-01 02:25:12,607 - django.utils.autoreload - INFO - C:\Users\puttu\OneDrive\Desktop\Vardaan\GRC_risk_module\backend\grc\views.py changed, reloading.
2025-06-01 02:25:21,215 - django.utils.autoreload - INFO - C:\Users\puttu\OneDrive\Desktop\Vardaan\GRC_risk_module\backend\grc\views.py changed, reloading.
2025-06-01 02:25:28,699 - django.utils.autoreload - INFO - C:\Users\puttu\OneDrive\Desktop\Vardaan\GRC_risk_module\backend\grc\urls.py changed, reloading.
2025-06-01 02:25:36,193 - django.utils.autoreload - INFO - C:\Users\puttu\OneDrive\Desktop\Vardaan\GRC_risk_module\backend\grc\views.py changed, reloading.
2025-06-01 02:25:45,943 - django.utils.autoreload - INFO - C:\Users\puttu\OneDrive\Desktop\Vardaan\GRC_risk_module\backend\grc\views.py changed, reloading.
2025-06-01 02:25:57,842 - django.utils.autoreload - INFO - C:\Users\puttu\OneDrive\Desktop\Vardaan\GRC_risk_module\backend\grc\views.py changed, reloading.
2025-06-01 02:26:53,463 - django.utils.autoreload - INFO - C:\Users\puttu\OneDrive\Desktop\Vardaan\GRC_risk_module\backend\grc\urls.py changed, reloading.
2025-06-01 02:28:08,723 - notification_service - INFO - Email sent successfully to syammuni916@gmail.com, type: riskMitigationAssigned
2025-06-01 02:41:25,881 - django.utils.autoreload - INFO - C:\Users\puttu\OneDrive\Desktop\Vardaan\GRC_risk_module\backend\grc\views.py changed, reloading.
2025-06-01 02:41:40,540 - django.utils.autoreload - INFO - C:\Users\puttu\OneDrive\Desktop\Vardaan\GRC_risk_module\backend\grc\views.py changed, reloading.
2025-06-01 02:41:47,499 - django.utils.autoreload - INFO - C:\Users\puttu\OneDrive\Desktop\Vardaan\GRC_risk_module\backend\grc\views.py changed, reloading.
2025-06-01 02:42:13,775 - django.utils.autoreload - INFO - C:\Users\puttu\OneDrive\Desktop\Vardaan\GRC_risk_module\backend\grc\views.py changed, reloading.
2025-06-01 02:42:49,471 - django.utils.autoreload - INFO - C:\Users\puttu\OneDrive\Desktop\Vardaan\GRC_risk_module\backend\grc\views.py changed, reloading.
2025-06-01 02:42:57,124 - django.utils.autoreload - INFO - C:\Users\puttu\OneDrive\Desktop\Vardaan\GRC_risk_module\backend\grc\views.py changed, reloading.
2025-06-01 02:43:39,498 - django.utils.autoreload - INFO - C:\Users\puttu\OneDrive\Desktop\Vardaan\GRC_risk_module\backend\grc\views.py changed, reloading.
2025-06-01 02:46:08,251 - django.utils.autoreload - INFO - C:\Users\puttu\OneDrive\Desktop\Vardaan\GRC_risk_module\backend\grc\notification_service.py changed, reloading.
2025-06-01 02:48:00,396 - django.utils.autoreload - INFO - C:\Users\puttu\OneDrive\Desktop\Vardaan\GRC_risk_module\backend\grc\views.py changed, reloading.
2025-06-01 02:48:07,970 - django.utils.autoreload - INFO - C:\Users\puttu\OneDrive\Desktop\Vardaan\GRC_risk_module\backend\grc\views.py changed, reloading.
2025-06-01 02:50:30,018 - django.utils.autoreload - INFO - C:\Users\puttu\OneDrive\Desktop\Vardaan\GRC_risk_module\backend\grc\views.py changed, reloading.
2025-06-01 02:50:51,242 - django.utils.autoreload - INFO - C:\Users\puttu\OneDrive\Desktop\Vardaan\GRC_risk_module\backend\grc\views.py changed, reloading.
2025-06-01 02:51:04,271 - django.utils.autoreload - INFO - C:\Users\puttu\OneDrive\Desktop\Vardaan\GRC_risk_module\backend\grc\views.py changed, reloading.
2025-06-01 02:51:12,471 - django.utils.autoreload - INFO - C:\Users\puttu\OneDrive\Desktop\Vardaan\GRC_risk_module\backend\grc\views.py changed, reloading.
2025-06-01 02:51:57,736 - notification_service - INFO - Email sent successfully to syammuni916@gmail.com, type: riskScoreUpdated
2025-06-01 02:52:01,625 - notification_service - INFO - Email sent successfully to syammuni916@gmail.com, type: riskScoreUpdated
2025-06-01 02:52:04,170 - notification_service - INFO - Email sent successfully to syammuni916@gmail.com, type: riskScoreUpdated
2025-06-01 02:52:07,806 - notification_service - INFO - Email sent successfully to syammuni916@gmail.com, type: riskScoreUpdated
2025-06-01 02:53:24,754 - django.request - ERROR - Internal Server Error: /api/assign-reviewer/
2025-06-01 02:54:25,188 - django.utils.autoreload - INFO - C:\Users\puttu\OneDrive\Desktop\Vardaan\GRC_risk_module\backend\grc\views.py changed, reloading.
2025-06-01 02:54:33,347 - django.utils.autoreload - INFO - C:\Users\puttu\OneDrive\Desktop\Vardaan\GRC_risk_module\backend\grc\views.py changed, reloading.
2025-06-01 02:54:53,294 - django.request - ERROR - Internal Server Error: /api/assign-reviewer/
2025-06-01 02:56:27,761 - django.utils.autoreload - INFO - C:\Users\puttu\OneDrive\Desktop\Vardaan\GRC_risk_module\backend\grc\views.py changed, reloading.
2025-06-01 02:56:35,336 - django.utils.autoreload - INFO - C:\Users\puttu\OneDrive\Desktop\Vardaan\GRC_risk_module\backend\grc\views.py changed, reloading.
2025-06-01 02:56:57,336 - notification_service - INFO - Email sent successfully to syammuni916@gmail.com, type: riskMitigationCompleted
2025-06-01 17:42:58,436 - django.utils.autoreload - INFO - C:\Users\puttu\Music\GRC_INTEGRATIONS\GRC\backend\grc\serializers.py changed, reloading.
2025-06-02 04:19:55,906 - django.request - ERROR - Internal Server Error: /api/policy-analytics/
2025-06-02 04:19:56,317 - django.request - ERROR - Internal Server Error: /api/policy-dashboard/
Traceback (most recent call last):
  File "C:\Users\puttu\AppData\Roaming\Python\Python310\site-packages\django\db\backends\utils.py", line 105, in _execute
    return self.cursor.execute(sql, params)
  File "C:\Users\puttu\AppData\Roaming\Python\Python310\site-packages\django\db\backends\mysql\base.py", line 76, in execute
    return self.cursor.execute(query, args)
  File "C:\Users\puttu\AppData\Roaming\Python\Python310\site-packages\pymysql\cursors.py", line 153, in execute
    result = self._query(query)
  File "C:\Users\puttu\AppData\Roaming\Python\Python310\site-packages\pymysql\cursors.py", line 322, in _query
    conn.query(q)
  File "C:\Users\puttu\AppData\Roaming\Python\Python310\site-packages\pymysql\connections.py", line 563, in query
    self._affected_rows = self._read_query_result(unbuffered=unbuffered)
  File "C:\Users\puttu\AppData\Roaming\Python\Python310\site-packages\pymysql\connections.py", line 825, in _read_query_result
    result.read()
  File "C:\Users\puttu\AppData\Roaming\Python\Python310\site-packages\pymysql\connections.py", line 1199, in read
    first_packet = self.connection._read_packet()
  File "C:\Users\puttu\AppData\Roaming\Python\Python310\site-packages\pymysql\connections.py", line 775, in _read_packet
    packet.raise_for_error()
  File "C:\Users\puttu\AppData\Roaming\Python\Python310\site-packages\pymysql\protocol.py", line 219, in raise_for_error
    err.raise_mysql_exception(self._data)
  File "C:\Users\puttu\AppData\Roaming\Python\Python310\site-packages\pymysql\err.py", line 150, in raise_mysql_exception
    raise errorclass(errno, errval)
pymysql.err.ProgrammingError: (1146, "Table 'grc_test.policies' doesn't exist")

The above exception was the direct cause of the following exception:

Traceback (most recent call last):
  File "C:\Users\puttu\AppData\Roaming\Python\Python310\site-packages\django\core\handlers\exception.py", line 55, in inner
    response = get_response(request)
  File "C:\Users\puttu\AppData\Roaming\Python\Python310\site-packages\django\core\handlers\base.py", line 197, in _get_response
    response = wrapped_callback(request, *callback_args, **callback_kwargs)
  File "C:\Users\puttu\AppData\Roaming\Python\Python310\site-packages\django\views\decorators\csrf.py", line 65, in _view_wrapper
    return view_func(request, *args, **kwargs)
  File "C:\Users\puttu\AppData\Roaming\Python\Python310\site-packages\django\views\generic\base.py", line 104, in view
    return self.dispatch(request, *args, **kwargs)
  File "C:\Users\puttu\AppData\Roaming\Python\Python310\site-packages\rest_framework\views.py", line 515, in dispatch
    response = self.handle_exception(exc)
  File "C:\Users\puttu\AppData\Roaming\Python\Python310\site-packages\rest_framework\views.py", line 475, in handle_exception
    self.raise_uncaught_exception(exc)
  File "C:\Users\puttu\AppData\Roaming\Python\Python310\site-packages\rest_framework\views.py", line 486, in raise_uncaught_exception
    raise exc
  File "C:\Users\puttu\AppData\Roaming\Python\Python310\site-packages\rest_framework\views.py", line 512, in dispatch
    response = handler(request, *args, **kwargs)
  File "C:\Users\puttu\AppData\Roaming\Python\Python310\site-packages\rest_framework\decorators.py", line 50, in handler
    return func(*args, **kwargs)
  File "C:\Users\puttu\Music\GRC_INTEGRATIONS\GRC\backend\grc\routes\policy.py", line 3947, in get_policy_dashboard_summary
    total_policies = Policy.objects.count()
  File "C:\Users\puttu\AppData\Roaming\Python\Python310\site-packages\django\db\models\manager.py", line 87, in manager_method
    return getattr(self.get_queryset(), name)(*args, **kwargs)
  File "C:\Users\puttu\AppData\Roaming\Python\Python310\site-packages\django\db\models\query.py", line 620, in count
    return self.query.get_count(using=self.db)
  File "C:\Users\puttu\AppData\Roaming\Python\Python310\site-packages\django\db\models\sql\query.py", line 630, in get_count
    return obj.get_aggregation(using, {"__count": Count("*")})["__count"]
  File "C:\Users\puttu\AppData\Roaming\Python\Python310\site-packages\django\db\models\sql\query.py", line 616, in get_aggregation
    result = compiler.execute_sql(SINGLE)
  File "C:\Users\puttu\AppData\Roaming\Python\Python310\site-packages\django\db\models\sql\compiler.py", line 1574, in execute_sql
    cursor.execute(sql, params)
  File "C:\Users\puttu\AppData\Roaming\Python\Python310\site-packages\django\db\backends\utils.py", line 122, in execute
    return super().execute(sql, params)
  File "C:\Users\puttu\AppData\Roaming\Python\Python310\site-packages\django\db\backends\utils.py", line 79, in execute
    return self._execute_with_wrappers(
  File "C:\Users\puttu\AppData\Roaming\Python\Python310\site-packages\django\db\backends\utils.py", line 92, in _execute_with_wrappers
    return executor(sql, params, many, context)
  File "C:\Users\puttu\AppData\Roaming\Python\Python310\site-packages\django\db\backends\utils.py", line 100, in _execute
    with self.db.wrap_database_errors:
  File "C:\Users\puttu\AppData\Roaming\Python\Python310\site-packages\django\db\utils.py", line 91, in __exit__
    raise dj_exc_value.with_traceback(traceback) from exc_value
  File "C:\Users\puttu\AppData\Roaming\Python\Python310\site-packages\django\db\backends\utils.py", line 105, in _execute
    return self.cursor.execute(sql, params)
  File "C:\Users\puttu\AppData\Roaming\Python\Python310\site-packages\django\db\backends\mysql\base.py", line 76, in execute
    return self.cursor.execute(query, args)
  File "C:\Users\puttu\AppData\Roaming\Python\Python310\site-packages\pymysql\cursors.py", line 153, in execute
    result = self._query(query)
  File "C:\Users\puttu\AppData\Roaming\Python\Python310\site-packages\pymysql\cursors.py", line 322, in _query
    conn.query(q)
  File "C:\Users\puttu\AppData\Roaming\Python\Python310\site-packages\pymysql\connections.py", line 563, in query
    self._affected_rows = self._read_query_result(unbuffered=unbuffered)
  File "C:\Users\puttu\AppData\Roaming\Python\Python310\site-packages\pymysql\connections.py", line 825, in _read_query_result
    result.read()
  File "C:\Users\puttu\AppData\Roaming\Python\Python310\site-packages\pymysql\connections.py", line 1199, in read
    first_packet = self.connection._read_packet()
  File "C:\Users\puttu\AppData\Roaming\Python\Python310\site-packages\pymysql\connections.py", line 775, in _read_packet
    packet.raise_for_error()
  File "C:\Users\puttu\AppData\Roaming\Python\Python310\site-packages\pymysql\protocol.py", line 219, in raise_for_error
    err.raise_mysql_exception(self._data)
  File "C:\Users\puttu\AppData\Roaming\Python\Python310\site-packages\pymysql\err.py", line 150, in raise_mysql_exception
    raise errorclass(errno, errval)
django.db.utils.ProgrammingError: (1146, "Table 'grc_test.policies' doesn't exist")
2025-06-02 04:19:56,402 - django.request - ERROR - Internal Server Error: /api/recent-policy-activity/
Traceback (most recent call last):
  File "C:\Users\puttu\AppData\Roaming\Python\Python310\site-packages\django\db\backends\utils.py", line 105, in _execute
    return self.cursor.execute(sql, params)
  File "C:\Users\puttu\AppData\Roaming\Python\Python310\site-packages\django\db\backends\mysql\base.py", line 76, in execute
    return self.cursor.execute(query, args)
  File "C:\Users\puttu\AppData\Roaming\Python\Python310\site-packages\pymysql\cursors.py", line 153, in execute
    result = self._query(query)
  File "C:\Users\puttu\AppData\Roaming\Python\Python310\site-packages\pymysql\cursors.py", line 322, in _query
    conn.query(q)
  File "C:\Users\puttu\AppData\Roaming\Python\Python310\site-packages\pymysql\connections.py", line 563, in query
    self._affected_rows = self._read_query_result(unbuffered=unbuffered)
  File "C:\Users\puttu\AppData\Roaming\Python\Python310\site-packages\pymysql\connections.py", line 825, in _read_query_result
    result.read()
  File "C:\Users\puttu\AppData\Roaming\Python\Python310\site-packages\pymysql\connections.py", line 1199, in read
    first_packet = self.connection._read_packet()
  File "C:\Users\puttu\AppData\Roaming\Python\Python310\site-packages\pymysql\connections.py", line 775, in _read_packet
    packet.raise_for_error()
  File "C:\Users\puttu\AppData\Roaming\Python\Python310\site-packages\pymysql\protocol.py", line 219, in raise_for_error
    err.raise_mysql_exception(self._data)
  File "C:\Users\puttu\AppData\Roaming\Python\Python310\site-packages\pymysql\err.py", line 150, in raise_mysql_exception
    raise errorclass(errno, errval)
pymysql.err.ProgrammingError: (1146, "Table 'grc_test.policies' doesn't exist")

The above exception was the direct cause of the following exception:

Traceback (most recent call last):
  File "C:\Users\puttu\AppData\Roaming\Python\Python310\site-packages\django\core\handlers\exception.py", line 55, in inner
    response = get_response(request)
  File "C:\Users\puttu\AppData\Roaming\Python\Python310\site-packages\django\core\handlers\base.py", line 197, in _get_response
    response = wrapped_callback(request, *callback_args, **callback_kwargs)
  File "C:\Users\puttu\AppData\Roaming\Python\Python310\site-packages\django\views\decorators\csrf.py", line 65, in _view_wrapper
    return view_func(request, *args, **kwargs)
  File "C:\Users\puttu\AppData\Roaming\Python\Python310\site-packages\django\views\generic\base.py", line 104, in view
    return self.dispatch(request, *args, **kwargs)
  File "C:\Users\puttu\AppData\Roaming\Python\Python310\site-packages\rest_framework\views.py", line 515, in dispatch
    response = self.handle_exception(exc)
  File "C:\Users\puttu\AppData\Roaming\Python\Python310\site-packages\rest_framework\views.py", line 475, in handle_exception
    self.raise_uncaught_exception(exc)
  File "C:\Users\puttu\AppData\Roaming\Python\Python310\site-packages\rest_framework\views.py", line 486, in raise_uncaught_exception
    raise exc
  File "C:\Users\puttu\AppData\Roaming\Python\Python310\site-packages\rest_framework\views.py", line 512, in dispatch
    response = handler(request, *args, **kwargs)
  File "C:\Users\puttu\AppData\Roaming\Python\Python310\site-packages\rest_framework\decorators.py", line 50, in handler
    return func(*args, **kwargs)
  File "C:\Users\puttu\Music\GRC_INTEGRATIONS\GRC\backend\grc\routes\policy.py", line 3991, in get_recent_policy_activity
    return Response([
  File "C:\Users\puttu\AppData\Roaming\Python\Python310\site-packages\django\db\models\query.py", line 400, in __iter__
    self._fetch_all()
  File "C:\Users\puttu\AppData\Roaming\Python\Python310\site-packages\django\db\models\query.py", line 1928, in _fetch_all
    self._result_cache = list(self._iterable_class(self))
  File "C:\Users\puttu\AppData\Roaming\Python\Python310\site-packages\django\db\models\query.py", line 91, in __iter__
    results = compiler.execute_sql(
  File "C:\Users\puttu\AppData\Roaming\Python\Python310\site-packages\django\db\models\sql\compiler.py", line 1574, in execute_sql
    cursor.execute(sql, params)
  File "C:\Users\puttu\AppData\Roaming\Python\Python310\site-packages\django\db\backends\utils.py", line 122, in execute
    return super().execute(sql, params)
  File "C:\Users\puttu\AppData\Roaming\Python\Python310\site-packages\django\db\backends\utils.py", line 79, in execute
    return self._execute_with_wrappers(
  File "C:\Users\puttu\AppData\Roaming\Python\Python310\site-packages\django\db\backends\utils.py", line 92, in _execute_with_wrappers
    return executor(sql, params, many, context)
  File "C:\Users\puttu\AppData\Roaming\Python\Python310\site-packages\django\db\backends\utils.py", line 100, in _execute
    with self.db.wrap_database_errors:
  File "C:\Users\puttu\AppData\Roaming\Python\Python310\site-packages\django\db\utils.py", line 91, in __exit__
    raise dj_exc_value.with_traceback(traceback) from exc_value
  File "C:\Users\puttu\AppData\Roaming\Python\Python310\site-packages\django\db\backends\utils.py", line 105, in _execute
    return self.cursor.execute(sql, params)
  File "C:\Users\puttu\AppData\Roaming\Python\Python310\site-packages\django\db\backends\mysql\base.py", line 76, in execute
    return self.cursor.execute(query, args)
  File "C:\Users\puttu\AppData\Roaming\Python\Python310\site-packages\pymysql\cursors.py", line 153, in execute
    result = self._query(query)
  File "C:\Users\puttu\AppData\Roaming\Python\Python310\site-packages\pymysql\cursors.py", line 322, in _query
    conn.query(q)
  File "C:\Users\puttu\AppData\Roaming\Python\Python310\site-packages\pymysql\connections.py", line 563, in query
    self._affected_rows = self._read_query_result(unbuffered=unbuffered)
  File "C:\Users\puttu\AppData\Roaming\Python\Python310\site-packages\pymysql\connections.py", line 825, in _read_query_result
    result.read()
  File "C:\Users\puttu\AppData\Roaming\Python\Python310\site-packages\pymysql\connections.py", line 1199, in read
    first_packet = self.connection._read_packet()
  File "C:\Users\puttu\AppData\Roaming\Python\Python310\site-packages\pymysql\connections.py", line 775, in _read_packet
    packet.raise_for_error()
  File "C:\Users\puttu\AppData\Roaming\Python\Python310\site-packages\pymysql\protocol.py", line 219, in raise_for_error
    err.raise_mysql_exception(self._data)
  File "C:\Users\puttu\AppData\Roaming\Python\Python310\site-packages\pymysql\err.py", line 150, in raise_mysql_exception
    raise errorclass(errno, errval)
django.db.utils.ProgrammingError: (1146, "Table 'grc_test.policies' doesn't exist")
2025-06-02 04:19:56,415 - django.request - ERROR - Internal Server Error: /api/policy-status-distribution/
Traceback (most recent call last):
  File "C:\Users\puttu\AppData\Roaming\Python\Python310\site-packages\django\db\backends\utils.py", line 105, in _execute
    return self.cursor.execute(sql, params)
  File "C:\Users\puttu\AppData\Roaming\Python\Python310\site-packages\django\db\backends\mysql\base.py", line 76, in execute
    return self.cursor.execute(query, args)
  File "C:\Users\puttu\AppData\Roaming\Python\Python310\site-packages\pymysql\cursors.py", line 153, in execute
    result = self._query(query)
  File "C:\Users\puttu\AppData\Roaming\Python\Python310\site-packages\pymysql\cursors.py", line 322, in _query
    conn.query(q)
  File "C:\Users\puttu\AppData\Roaming\Python\Python310\site-packages\pymysql\connections.py", line 563, in query
    self._affected_rows = self._read_query_result(unbuffered=unbuffered)
  File "C:\Users\puttu\AppData\Roaming\Python\Python310\site-packages\pymysql\connections.py", line 825, in _read_query_result
    result.read()
  File "C:\Users\puttu\AppData\Roaming\Python\Python310\site-packages\pymysql\connections.py", line 1199, in read
    first_packet = self.connection._read_packet()
  File "C:\Users\puttu\AppData\Roaming\Python\Python310\site-packages\pymysql\connections.py", line 775, in _read_packet
    packet.raise_for_error()
  File "C:\Users\puttu\AppData\Roaming\Python\Python310\site-packages\pymysql\protocol.py", line 219, in raise_for_error
    err.raise_mysql_exception(self._data)
  File "C:\Users\puttu\AppData\Roaming\Python\Python310\site-packages\pymysql\err.py", line 150, in raise_mysql_exception
    raise errorclass(errno, errval)
pymysql.err.ProgrammingError: (1146, "Table 'grc_test.policies' doesn't exist")

The above exception was the direct cause of the following exception:

Traceback (most recent call last):
  File "C:\Users\puttu\AppData\Roaming\Python\Python310\site-packages\django\core\handlers\exception.py", line 55, in inner
    response = get_response(request)
  File "C:\Users\puttu\AppData\Roaming\Python\Python310\site-packages\django\core\handlers\base.py", line 220, in _get_response
    response = response.render()
  File "C:\Users\puttu\AppData\Roaming\Python\Python310\site-packages\django\template\response.py", line 114, in render
    self.content = self.rendered_content
  File "C:\Users\puttu\AppData\Roaming\Python\Python310\site-packages\rest_framework\response.py", line 74, in rendered_content
    ret = renderer.render(self.data, accepted_media_type, context)
  File "C:\Users\puttu\AppData\Roaming\Python\Python310\site-packages\rest_framework\renderers.py", line 100, in render
    ret = json.dumps(
  File "C:\Users\puttu\AppData\Roaming\Python\Python310\site-packages\rest_framework\utils\json.py", line 25, in dumps
    return json.dumps(*args, **kwargs)
  File "C:\Program Files\Python310\lib\json\__init__.py", line 238, in dumps
    **kw).encode(obj)
  File "C:\Program Files\Python310\lib\json\encoder.py", line 199, in encode
    chunks = self.iterencode(o, _one_shot=True)
  File "C:\Program Files\Python310\lib\json\encoder.py", line 257, in iterencode
    return _iterencode(o, 0)
  File "C:\Users\puttu\AppData\Roaming\Python\Python310\site-packages\rest_framework\utils\encoders.py", line 49, in default
    return tuple(obj)
  File "C:\Users\puttu\AppData\Roaming\Python\Python310\site-packages\django\db\models\query.py", line 400, in __iter__
    self._fetch_all()
  File "C:\Users\puttu\AppData\Roaming\Python\Python310\site-packages\django\db\models\query.py", line 1928, in _fetch_all
    self._result_cache = list(self._iterable_class(self))
  File "C:\Users\puttu\AppData\Roaming\Python\Python310\site-packages\django\db\models\query.py", line 210, in __iter__
    for row in compiler.results_iter(
  File "C:\Users\puttu\AppData\Roaming\Python\Python310\site-packages\django\db\models\sql\compiler.py", line 1525, in results_iter
    results = self.execute_sql(
  File "C:\Users\puttu\AppData\Roaming\Python\Python310\site-packages\django\db\models\sql\compiler.py", line 1574, in execute_sql
    cursor.execute(sql, params)
  File "C:\Users\puttu\AppData\Roaming\Python\Python310\site-packages\django\db\backends\utils.py", line 122, in execute
    return super().execute(sql, params)
  File "C:\Users\puttu\AppData\Roaming\Python\Python310\site-packages\django\db\backends\utils.py", line 79, in execute
    return self._execute_with_wrappers(
  File "C:\Users\puttu\AppData\Roaming\Python\Python310\site-packages\django\db\backends\utils.py", line 92, in _execute_with_wrappers
    return executor(sql, params, many, context)
  File "C:\Users\puttu\AppData\Roaming\Python\Python310\site-packages\django\db\backends\utils.py", line 100, in _execute
    with self.db.wrap_database_errors:
  File "C:\Users\puttu\AppData\Roaming\Python\Python310\site-packages\django\db\utils.py", line 91, in __exit__
    raise dj_exc_value.with_traceback(traceback) from exc_value
  File "C:\Users\puttu\AppData\Roaming\Python\Python310\site-packages\django\db\backends\utils.py", line 105, in _execute
    return self.cursor.execute(sql, params)
  File "C:\Users\puttu\AppData\Roaming\Python\Python310\site-packages\django\db\backends\mysql\base.py", line 76, in execute
    return self.cursor.execute(query, args)
  File "C:\Users\puttu\AppData\Roaming\Python\Python310\site-packages\pymysql\cursors.py", line 153, in execute
    result = self._query(query)
  File "C:\Users\puttu\AppData\Roaming\Python\Python310\site-packages\pymysql\cursors.py", line 322, in _query
    conn.query(q)
  File "C:\Users\puttu\AppData\Roaming\Python\Python310\site-packages\pymysql\connections.py", line 563, in query
    self._affected_rows = self._read_query_result(unbuffered=unbuffered)
  File "C:\Users\puttu\AppData\Roaming\Python\Python310\site-packages\pymysql\connections.py", line 825, in _read_query_result
    result.read()
  File "C:\Users\puttu\AppData\Roaming\Python\Python310\site-packages\pymysql\connections.py", line 1199, in read
    first_packet = self.connection._read_packet()
  File "C:\Users\puttu\AppData\Roaming\Python\Python310\site-packages\pymysql\connections.py", line 775, in _read_packet
    packet.raise_for_error()
  File "C:\Users\puttu\AppData\Roaming\Python\Python310\site-packages\pymysql\protocol.py", line 219, in raise_for_error
    err.raise_mysql_exception(self._data)
  File "C:\Users\puttu\AppData\Roaming\Python\Python310\site-packages\pymysql\err.py", line 150, in raise_mysql_exception
    raise errorclass(errno, errval)
django.db.utils.ProgrammingError: (1146, "Table 'grc_test.policies' doesn't exist")
2025-06-02 04:19:56,415 - django.request - ERROR - Internal Server Error: /api/reviewer-workload/
Traceback (most recent call last):
  File "C:\Users\puttu\AppData\Roaming\Python\Python310\site-packages\django\db\backends\utils.py", line 105, in _execute
    return self.cursor.execute(sql, params)
  File "C:\Users\puttu\AppData\Roaming\Python\Python310\site-packages\django\db\backends\mysql\base.py", line 76, in execute
    return self.cursor.execute(query, args)
  File "C:\Users\puttu\AppData\Roaming\Python\Python310\site-packages\pymysql\cursors.py", line 153, in execute
    result = self._query(query)
  File "C:\Users\puttu\AppData\Roaming\Python\Python310\site-packages\pymysql\cursors.py", line 322, in _query
    conn.query(q)
  File "C:\Users\puttu\AppData\Roaming\Python\Python310\site-packages\pymysql\connections.py", line 563, in query
    self._affected_rows = self._read_query_result(unbuffered=unbuffered)
  File "C:\Users\puttu\AppData\Roaming\Python\Python310\site-packages\pymysql\connections.py", line 825, in _read_query_result
    result.read()
  File "C:\Users\puttu\AppData\Roaming\Python\Python310\site-packages\pymysql\connections.py", line 1199, in read
    first_packet = self.connection._read_packet()
  File "C:\Users\puttu\AppData\Roaming\Python\Python310\site-packages\pymysql\connections.py", line 775, in _read_packet
    packet.raise_for_error()
  File "C:\Users\puttu\AppData\Roaming\Python\Python310\site-packages\pymysql\protocol.py", line 219, in raise_for_error
    err.raise_mysql_exception(self._data)
  File "C:\Users\puttu\AppData\Roaming\Python\Python310\site-packages\pymysql\err.py", line 150, in raise_mysql_exception
    raise errorclass(errno, errval)
pymysql.err.ProgrammingError: (1146, "Table 'grc_test.policies' doesn't exist")

The above exception was the direct cause of the following exception:

Traceback (most recent call last):
  File "C:\Users\puttu\AppData\Roaming\Python\Python310\site-packages\django\core\handlers\exception.py", line 55, in inner
    response = get_response(request)
  File "C:\Users\puttu\AppData\Roaming\Python\Python310\site-packages\django\core\handlers\base.py", line 220, in _get_response
    response = response.render()
  File "C:\Users\puttu\AppData\Roaming\Python\Python310\site-packages\django\template\response.py", line 114, in render
    self.content = self.rendered_content
  File "C:\Users\puttu\AppData\Roaming\Python\Python310\site-packages\rest_framework\response.py", line 74, in rendered_content
    ret = renderer.render(self.data, accepted_media_type, context)
  File "C:\Users\puttu\AppData\Roaming\Python\Python310\site-packages\rest_framework\renderers.py", line 100, in render
    ret = json.dumps(
  File "C:\Users\puttu\AppData\Roaming\Python\Python310\site-packages\rest_framework\utils\json.py", line 25, in dumps
    return json.dumps(*args, **kwargs)
  File "C:\Program Files\Python310\lib\json\__init__.py", line 238, in dumps
    **kw).encode(obj)
  File "C:\Program Files\Python310\lib\json\encoder.py", line 199, in encode
    chunks = self.iterencode(o, _one_shot=True)
  File "C:\Program Files\Python310\lib\json\encoder.py", line 257, in iterencode
    return _iterencode(o, 0)
  File "C:\Users\puttu\AppData\Roaming\Python\Python310\site-packages\rest_framework\utils\encoders.py", line 49, in default
    return tuple(obj)
  File "C:\Users\puttu\AppData\Roaming\Python\Python310\site-packages\django\db\models\query.py", line 400, in __iter__
    self._fetch_all()
  File "C:\Users\puttu\AppData\Roaming\Python\Python310\site-packages\django\db\models\query.py", line 1928, in _fetch_all
    self._result_cache = list(self._iterable_class(self))
  File "C:\Users\puttu\AppData\Roaming\Python\Python310\site-packages\django\db\models\query.py", line 210, in __iter__
    for row in compiler.results_iter(
  File "C:\Users\puttu\AppData\Roaming\Python\Python310\site-packages\django\db\models\sql\compiler.py", line 1525, in results_iter
    results = self.execute_sql(
  File "C:\Users\puttu\AppData\Roaming\Python\Python310\site-packages\django\db\models\sql\compiler.py", line 1574, in execute_sql
    cursor.execute(sql, params)
  File "C:\Users\puttu\AppData\Roaming\Python\Python310\site-packages\django\db\backends\utils.py", line 122, in execute
    return super().execute(sql, params)
  File "C:\Users\puttu\AppData\Roaming\Python\Python310\site-packages\django\db\backends\utils.py", line 79, in execute
    return self._execute_with_wrappers(
  File "C:\Users\puttu\AppData\Roaming\Python\Python310\site-packages\django\db\backends\utils.py", line 92, in _execute_with_wrappers
    return executor(sql, params, many, context)
  File "C:\Users\puttu\AppData\Roaming\Python\Python310\site-packages\django\db\backends\utils.py", line 100, in _execute
    with self.db.wrap_database_errors:
  File "C:\Users\puttu\AppData\Roaming\Python\Python310\site-packages\django\db\utils.py", line 91, in __exit__
    raise dj_exc_value.with_traceback(traceback) from exc_value
  File "C:\Users\puttu\AppData\Roaming\Python\Python310\site-packages\django\db\backends\utils.py", line 105, in _execute
    return self.cursor.execute(sql, params)
  File "C:\Users\puttu\AppData\Roaming\Python\Python310\site-packages\django\db\backends\mysql\base.py", line 76, in execute
    return self.cursor.execute(query, args)
  File "C:\Users\puttu\AppData\Roaming\Python\Python310\site-packages\pymysql\cursors.py", line 153, in execute
    result = self._query(query)
  File "C:\Users\puttu\AppData\Roaming\Python\Python310\site-packages\pymysql\cursors.py", line 322, in _query
    conn.query(q)
  File "C:\Users\puttu\AppData\Roaming\Python\Python310\site-packages\pymysql\connections.py", line 563, in query
    self._affected_rows = self._read_query_result(unbuffered=unbuffered)
  File "C:\Users\puttu\AppData\Roaming\Python\Python310\site-packages\pymysql\connections.py", line 825, in _read_query_result
    result.read()
  File "C:\Users\puttu\AppData\Roaming\Python\Python310\site-packages\pymysql\connections.py", line 1199, in read
    first_packet = self.connection._read_packet()
  File "C:\Users\puttu\AppData\Roaming\Python\Python310\site-packages\pymysql\connections.py", line 775, in _read_packet
    packet.raise_for_error()
  File "C:\Users\puttu\AppData\Roaming\Python\Python310\site-packages\pymysql\protocol.py", line 219, in raise_for_error
    err.raise_mysql_exception(self._data)
  File "C:\Users\puttu\AppData\Roaming\Python\Python310\site-packages\pymysql\err.py", line 150, in raise_mysql_exception
    raise errorclass(errno, errval)
django.db.utils.ProgrammingError: (1146, "Table 'grc_test.policies' doesn't exist")
2025-06-02 04:19:56,439 - django.request - ERROR - Internal Server Error: /api/avg-policy-approval-time/
Traceback (most recent call last):
  File "C:\Users\puttu\AppData\Roaming\Python\Python310\site-packages\django\db\backends\utils.py", line 105, in _execute
    return self.cursor.execute(sql, params)
  File "C:\Users\puttu\AppData\Roaming\Python\Python310\site-packages\django\db\backends\mysql\base.py", line 76, in execute
    return self.cursor.execute(query, args)
  File "C:\Users\puttu\AppData\Roaming\Python\Python310\site-packages\pymysql\cursors.py", line 153, in execute
    result = self._query(query)
  File "C:\Users\puttu\AppData\Roaming\Python\Python310\site-packages\pymysql\cursors.py", line 322, in _query
    conn.query(q)
  File "C:\Users\puttu\AppData\Roaming\Python\Python310\site-packages\pymysql\connections.py", line 563, in query
    self._affected_rows = self._read_query_result(unbuffered=unbuffered)
  File "C:\Users\puttu\AppData\Roaming\Python\Python310\site-packages\pymysql\connections.py", line 825, in _read_query_result
    result.read()
  File "C:\Users\puttu\AppData\Roaming\Python\Python310\site-packages\pymysql\connections.py", line 1199, in read
    first_packet = self.connection._read_packet()
  File "C:\Users\puttu\AppData\Roaming\Python\Python310\site-packages\pymysql\connections.py", line 775, in _read_packet
    packet.raise_for_error()
  File "C:\Users\puttu\AppData\Roaming\Python\Python310\site-packages\pymysql\protocol.py", line 219, in raise_for_error
    err.raise_mysql_exception(self._data)
  File "C:\Users\puttu\AppData\Roaming\Python\Python310\site-packages\pymysql\err.py", line 150, in raise_mysql_exception
    raise errorclass(errno, errval)
pymysql.err.ProgrammingError: (1146, "Table 'grc_test.policyapproval' doesn't exist")

The above exception was the direct cause of the following exception:

Traceback (most recent call last):
  File "C:\Users\puttu\AppData\Roaming\Python\Python310\site-packages\django\core\handlers\exception.py", line 55, in inner
    response = get_response(request)
  File "C:\Users\puttu\AppData\Roaming\Python\Python310\site-packages\django\core\handlers\base.py", line 197, in _get_response
    response = wrapped_callback(request, *callback_args, **callback_kwargs)
  File "C:\Users\puttu\AppData\Roaming\Python\Python310\site-packages\django\views\decorators\csrf.py", line 65, in _view_wrapper
    return view_func(request, *args, **kwargs)
  File "C:\Users\puttu\AppData\Roaming\Python\Python310\site-packages\django\views\generic\base.py", line 104, in view
    return self.dispatch(request, *args, **kwargs)
  File "C:\Users\puttu\AppData\Roaming\Python\Python310\site-packages\rest_framework\views.py", line 515, in dispatch
    response = self.handle_exception(exc)
  File "C:\Users\puttu\AppData\Roaming\Python\Python310\site-packages\rest_framework\views.py", line 475, in handle_exception
    self.raise_uncaught_exception(exc)
  File "C:\Users\puttu\AppData\Roaming\Python\Python310\site-packages\rest_framework\views.py", line 486, in raise_uncaught_exception
    raise exc
  File "C:\Users\puttu\AppData\Roaming\Python\Python310\site-packages\rest_framework\views.py", line 512, in dispatch
    response = handler(request, *args, **kwargs)
  File "C:\Users\puttu\AppData\Roaming\Python\Python310\site-packages\rest_framework\decorators.py", line 50, in handler
    return func(*args, **kwargs)
  File "C:\Users\puttu\Music\GRC_INTEGRATIONS\GRC\backend\grc\routes\policy.py", line 4010, in get_avg_policy_approval_time
    if not approved_policies:
  File "C:\Users\puttu\AppData\Roaming\Python\Python310\site-packages\django\db\models\query.py", line 414, in __bool__
    self._fetch_all()
  File "C:\Users\puttu\AppData\Roaming\Python\Python310\site-packages\django\db\models\query.py", line 1928, in _fetch_all
    self._result_cache = list(self._iterable_class(self))
  File "C:\Users\puttu\AppData\Roaming\Python\Python310\site-packages\django\db\models\query.py", line 91, in __iter__
    results = compiler.execute_sql(
  File "C:\Users\puttu\AppData\Roaming\Python\Python310\site-packages\django\db\models\sql\compiler.py", line 1574, in execute_sql
    cursor.execute(sql, params)
  File "C:\Users\puttu\AppData\Roaming\Python\Python310\site-packages\django\db\backends\utils.py", line 122, in execute
    return super().execute(sql, params)
  File "C:\Users\puttu\AppData\Roaming\Python\Python310\site-packages\django\db\backends\utils.py", line 79, in execute
    return self._execute_with_wrappers(
  File "C:\Users\puttu\AppData\Roaming\Python\Python310\site-packages\django\db\backends\utils.py", line 92, in _execute_with_wrappers
    return executor(sql, params, many, context)
  File "C:\Users\puttu\AppData\Roaming\Python\Python310\site-packages\django\db\backends\utils.py", line 100, in _execute
    with self.db.wrap_database_errors:
  File "C:\Users\puttu\AppData\Roaming\Python\Python310\site-packages\django\db\utils.py", line 91, in __exit__
    raise dj_exc_value.with_traceback(traceback) from exc_value
  File "C:\Users\puttu\AppData\Roaming\Python\Python310\site-packages\django\db\backends\utils.py", line 105, in _execute
    return self.cursor.execute(sql, params)
  File "C:\Users\puttu\AppData\Roaming\Python\Python310\site-packages\django\db\backends\mysql\base.py", line 76, in execute
    return self.cursor.execute(query, args)
  File "C:\Users\puttu\AppData\Roaming\Python\Python310\site-packages\pymysql\cursors.py", line 153, in execute
    result = self._query(query)
  File "C:\Users\puttu\AppData\Roaming\Python\Python310\site-packages\pymysql\cursors.py", line 322, in _query
    conn.query(q)
  File "C:\Users\puttu\AppData\Roaming\Python\Python310\site-packages\pymysql\connections.py", line 563, in query
    self._affected_rows = self._read_query_result(unbuffered=unbuffered)
  File "C:\Users\puttu\AppData\Roaming\Python\Python310\site-packages\pymysql\connections.py", line 825, in _read_query_result
    result.read()
  File "C:\Users\puttu\AppData\Roaming\Python\Python310\site-packages\pymysql\connections.py", line 1199, in read
    first_packet = self.connection._read_packet()
  File "C:\Users\puttu\AppData\Roaming\Python\Python310\site-packages\pymysql\connections.py", line 775, in _read_packet
    packet.raise_for_error()
  File "C:\Users\puttu\AppData\Roaming\Python\Python310\site-packages\pymysql\protocol.py", line 219, in raise_for_error
    err.raise_mysql_exception(self._data)
  File "C:\Users\puttu\AppData\Roaming\Python\Python310\site-packages\pymysql\err.py", line 150, in raise_mysql_exception
    raise errorclass(errno, errval)
django.db.utils.ProgrammingError: (1146, "Table 'grc_test.policyapproval' doesn't exist")
2025-06-02 04:20:41,336 - django.utils.autoreload - INFO - C:\Users\puttu\Music\GRC_INTEGRATIONS\GRC\backend\backend\settings.py changed, reloading.
2025-06-02 04:21:16,990 - django.request - ERROR - Internal Server Error: /api/risks/
Traceback (most recent call last):
  File "C:\Users\puttu\AppData\Roaming\Python\Python310\site-packages\django\db\backends\utils.py", line 105, in _execute
    return self.cursor.execute(sql, params)
  File "C:\Users\puttu\AppData\Roaming\Python\Python310\site-packages\django\db\backends\mysql\base.py", line 76, in execute
    return self.cursor.execute(query, args)
  File "C:\Users\puttu\AppData\Roaming\Python\Python310\site-packages\pymysql\cursors.py", line 153, in execute
    result = self._query(query)
  File "C:\Users\puttu\AppData\Roaming\Python\Python310\site-packages\pymysql\cursors.py", line 322, in _query
    conn.query(q)
  File "C:\Users\puttu\AppData\Roaming\Python\Python310\site-packages\pymysql\connections.py", line 563, in query
    self._affected_rows = self._read_query_result(unbuffered=unbuffered)
  File "C:\Users\puttu\AppData\Roaming\Python\Python310\site-packages\pymysql\connections.py", line 825, in _read_query_result
    result.read()
  File "C:\Users\puttu\AppData\Roaming\Python\Python310\site-packages\pymysql\connections.py", line 1199, in read
    first_packet = self.connection._read_packet()
  File "C:\Users\puttu\AppData\Roaming\Python\Python310\site-packages\pymysql\connections.py", line 775, in _read_packet
    packet.raise_for_error()
  File "C:\Users\puttu\AppData\Roaming\Python\Python310\site-packages\pymysql\protocol.py", line 219, in raise_for_error
    err.raise_mysql_exception(self._data)
  File "C:\Users\puttu\AppData\Roaming\Python\Python310\site-packages\pymysql\err.py", line 150, in raise_mysql_exception
    raise errorclass(errno, errval)
pymysql.err.OperationalError: (1054, "Unknown column 'risk.RiskPriority' in 'field list'")

The above exception was the direct cause of the following exception:

Traceback (most recent call last):
  File "C:\Users\puttu\AppData\Roaming\Python\Python310\site-packages\django\core\handlers\exception.py", line 55, in inner
    response = get_response(request)
  File "C:\Users\puttu\AppData\Roaming\Python\Python310\site-packages\django\core\handlers\base.py", line 197, in _get_response
    response = wrapped_callback(request, *callback_args, **callback_kwargs)
  File "C:\Users\puttu\AppData\Roaming\Python\Python310\site-packages\django\views\decorators\csrf.py", line 65, in _view_wrapper
    return view_func(request, *args, **kwargs)
  File "C:\Users\puttu\AppData\Roaming\Python\Python310\site-packages\rest_framework\viewsets.py", line 125, in view
    return self.dispatch(request, *args, **kwargs)
  File "C:\Users\puttu\AppData\Roaming\Python\Python310\site-packages\rest_framework\views.py", line 515, in dispatch
    response = self.handle_exception(exc)
  File "C:\Users\puttu\AppData\Roaming\Python\Python310\site-packages\rest_framework\views.py", line 475, in handle_exception
    self.raise_uncaught_exception(exc)
  File "C:\Users\puttu\AppData\Roaming\Python\Python310\site-packages\rest_framework\views.py", line 486, in raise_uncaught_exception
    raise exc
  File "C:\Users\puttu\AppData\Roaming\Python\Python310\site-packages\rest_framework\views.py", line 512, in dispatch
    response = handler(request, *args, **kwargs)
  File "C:\Users\puttu\Music\GRC_INTEGRATIONS\GRC\backend\grc\views.py", line 1008, in list
    return super().list(request)
  File "C:\Users\puttu\AppData\Roaming\Python\Python310\site-packages\rest_framework\mixins.py", line 46, in list
    return Response(serializer.data)
  File "C:\Users\puttu\AppData\Roaming\Python\Python310\site-packages\rest_framework\serializers.py", line 797, in data
    ret = super().data
  File "C:\Users\puttu\AppData\Roaming\Python\Python310\site-packages\rest_framework\serializers.py", line 251, in data
    self._data = self.to_representation(self.instance)
  File "C:\Users\puttu\AppData\Roaming\Python\Python310\site-packages\rest_framework\serializers.py", line 715, in to_representation
    return [
  File "C:\Users\puttu\AppData\Roaming\Python\Python310\site-packages\django\db\models\query.py", line 400, in __iter__
    self._fetch_all()
  File "C:\Users\puttu\AppData\Roaming\Python\Python310\site-packages\django\db\models\query.py", line 1928, in _fetch_all
    self._result_cache = list(self._iterable_class(self))
  File "C:\Users\puttu\AppData\Roaming\Python\Python310\site-packages\django\db\models\query.py", line 91, in __iter__
    results = compiler.execute_sql(
  File "C:\Users\puttu\AppData\Roaming\Python\Python310\site-packages\django\db\models\sql\compiler.py", line 1574, in execute_sql
    cursor.execute(sql, params)
  File "C:\Users\puttu\AppData\Roaming\Python\Python310\site-packages\django\db\backends\utils.py", line 122, in execute
    return super().execute(sql, params)
  File "C:\Users\puttu\AppData\Roaming\Python\Python310\site-packages\django\db\backends\utils.py", line 79, in execute
    return self._execute_with_wrappers(
  File "C:\Users\puttu\AppData\Roaming\Python\Python310\site-packages\django\db\backends\utils.py", line 92, in _execute_with_wrappers
    return executor(sql, params, many, context)
  File "C:\Users\puttu\AppData\Roaming\Python\Python310\site-packages\django\db\backends\utils.py", line 100, in _execute
    with self.db.wrap_database_errors:
  File "C:\Users\puttu\AppData\Roaming\Python\Python310\site-packages\django\db\utils.py", line 91, in __exit__
    raise dj_exc_value.with_traceback(traceback) from exc_value
  File "C:\Users\puttu\AppData\Roaming\Python\Python310\site-packages\django\db\backends\utils.py", line 105, in _execute
    return self.cursor.execute(sql, params)
  File "C:\Users\puttu\AppData\Roaming\Python\Python310\site-packages\django\db\backends\mysql\base.py", line 76, in execute
    return self.cursor.execute(query, args)
  File "C:\Users\puttu\AppData\Roaming\Python\Python310\site-packages\pymysql\cursors.py", line 153, in execute
    result = self._query(query)
  File "C:\Users\puttu\AppData\Roaming\Python\Python310\site-packages\pymysql\cursors.py", line 322, in _query
    conn.query(q)
  File "C:\Users\puttu\AppData\Roaming\Python\Python310\site-packages\pymysql\connections.py", line 563, in query
    self._affected_rows = self._read_query_result(unbuffered=unbuffered)
  File "C:\Users\puttu\AppData\Roaming\Python\Python310\site-packages\pymysql\connections.py", line 825, in _read_query_result
    result.read()
  File "C:\Users\puttu\AppData\Roaming\Python\Python310\site-packages\pymysql\connections.py", line 1199, in read
    first_packet = self.connection._read_packet()
  File "C:\Users\puttu\AppData\Roaming\Python\Python310\site-packages\pymysql\connections.py", line 775, in _read_packet
    packet.raise_for_error()
  File "C:\Users\puttu\AppData\Roaming\Python\Python310\site-packages\pymysql\protocol.py", line 219, in raise_for_error
    err.raise_mysql_exception(self._data)
  File "C:\Users\puttu\AppData\Roaming\Python\Python310\site-packages\pymysql\err.py", line 150, in raise_mysql_exception
    raise errorclass(errno, errval)
django.db.utils.OperationalError: (1054, "Unknown column 'risk.RiskPriority' in 'field list'")
2025-06-02 04:40:47,582 - django.request - WARNING - Unauthorized: /api/users/
2025-06-02 04:40:52,008 - django.request - WARNING - Unauthorized: /api/users/
2025-06-02 04:40:53,035 - django.request - WARNING - Unauthorized: /api/users/
2025-06-02 04:41:04,175 - django.request - WARNING - Not Found: /api/all-policies/framework-versions/1/
2025-06-02 04:41:26,865 - django.request - WARNING - Not Found: /api/policy-approvals/latest/1083/
2025-06-02 04:46:47,040 - django.request - WARNING - Not Found: /api/policy-approvals/latest/1084/
2025-06-02 04:47:27,260 - django.request - WARNING - Unauthorized: /api/users/
2025-06-02 04:47:42,467 - django.request - WARNING - Unauthorized: /api/users/
2025-06-02 04:47:50,861 - django.request - WARNING - Forbidden: /api/frameworks/16/
<<<<<<< HEAD
2025-06-02 04:50:53,984 - django.utils.autoreload - INFO - C:\Users\puttu\Music\GRC_INTEGRATIONS\GRC\backend\grc\models.py changed, reloading.
=======
>>>>>>> RiskModule_01_06
2025-06-02 10:13:27,058 - django.request - ERROR - Internal Server Error: /api/risks/
Traceback (most recent call last):
  File "C:\Users\puttu\AppData\Roaming\Python\Python310\site-packages\django\db\backends\utils.py", line 105, in _execute
    return self.cursor.execute(sql, params)
  File "C:\Users\puttu\AppData\Roaming\Python\Python310\site-packages\django\db\backends\mysql\base.py", line 76, in execute
    return self.cursor.execute(query, args)
  File "C:\Users\puttu\AppData\Roaming\Python\Python310\site-packages\pymysql\cursors.py", line 153, in execute
    result = self._query(query)
  File "C:\Users\puttu\AppData\Roaming\Python\Python310\site-packages\pymysql\cursors.py", line 322, in _query
    conn.query(q)
  File "C:\Users\puttu\AppData\Roaming\Python\Python310\site-packages\pymysql\connections.py", line 563, in query
    self._affected_rows = self._read_query_result(unbuffered=unbuffered)
  File "C:\Users\puttu\AppData\Roaming\Python\Python310\site-packages\pymysql\connections.py", line 825, in _read_query_result
    result.read()
  File "C:\Users\puttu\AppData\Roaming\Python\Python310\site-packages\pymysql\connections.py", line 1199, in read
    first_packet = self.connection._read_packet()
  File "C:\Users\puttu\AppData\Roaming\Python\Python310\site-packages\pymysql\connections.py", line 775, in _read_packet
    packet.raise_for_error()
  File "C:\Users\puttu\AppData\Roaming\Python\Python310\site-packages\pymysql\protocol.py", line 219, in raise_for_error
    err.raise_mysql_exception(self._data)
  File "C:\Users\puttu\AppData\Roaming\Python\Python310\site-packages\pymysql\err.py", line 150, in raise_mysql_exception
    raise errorclass(errno, errval)
pymysql.err.OperationalError: (1054, "Unknown column 'risk.RiskPriority' in 'field list'")

The above exception was the direct cause of the following exception:

Traceback (most recent call last):
  File "C:\Users\puttu\AppData\Roaming\Python\Python310\site-packages\django\core\handlers\exception.py", line 55, in inner
    response = get_response(request)
  File "C:\Users\puttu\AppData\Roaming\Python\Python310\site-packages\django\core\handlers\base.py", line 197, in _get_response
    response = wrapped_callback(request, *callback_args, **callback_kwargs)
  File "C:\Users\puttu\AppData\Roaming\Python\Python310\site-packages\django\views\decorators\csrf.py", line 65, in _view_wrapper
    return view_func(request, *args, **kwargs)
  File "C:\Users\puttu\AppData\Roaming\Python\Python310\site-packages\rest_framework\viewsets.py", line 125, in view
    return self.dispatch(request, *args, **kwargs)
  File "C:\Users\puttu\AppData\Roaming\Python\Python310\site-packages\rest_framework\views.py", line 515, in dispatch
    response = self.handle_exception(exc)
  File "C:\Users\puttu\AppData\Roaming\Python\Python310\site-packages\rest_framework\views.py", line 475, in handle_exception
    self.raise_uncaught_exception(exc)
  File "C:\Users\puttu\AppData\Roaming\Python\Python310\site-packages\rest_framework\views.py", line 486, in raise_uncaught_exception
    raise exc
  File "C:\Users\puttu\AppData\Roaming\Python\Python310\site-packages\rest_framework\views.py", line 512, in dispatch
    response = handler(request, *args, **kwargs)
  File "C:\Users\puttu\Music\GRC_INTEGRATIONS\GRC\GRC\backend\grc\views.py", line 1008, in list
    return super().list(request)
  File "C:\Users\puttu\AppData\Roaming\Python\Python310\site-packages\rest_framework\mixins.py", line 46, in list
    return Response(serializer.data)
  File "C:\Users\puttu\AppData\Roaming\Python\Python310\site-packages\rest_framework\serializers.py", line 797, in data
    ret = super().data
  File "C:\Users\puttu\AppData\Roaming\Python\Python310\site-packages\rest_framework\serializers.py", line 251, in data
    self._data = self.to_representation(self.instance)
  File "C:\Users\puttu\AppData\Roaming\Python\Python310\site-packages\rest_framework\serializers.py", line 715, in to_representation
    return [
  File "C:\Users\puttu\AppData\Roaming\Python\Python310\site-packages\django\db\models\query.py", line 400, in __iter__
    self._fetch_all()
  File "C:\Users\puttu\AppData\Roaming\Python\Python310\site-packages\django\db\models\query.py", line 1928, in _fetch_all
    self._result_cache = list(self._iterable_class(self))
  File "C:\Users\puttu\AppData\Roaming\Python\Python310\site-packages\django\db\models\query.py", line 91, in __iter__
    results = compiler.execute_sql(
  File "C:\Users\puttu\AppData\Roaming\Python\Python310\site-packages\django\db\models\sql\compiler.py", line 1574, in execute_sql
    cursor.execute(sql, params)
  File "C:\Users\puttu\AppData\Roaming\Python\Python310\site-packages\django\db\backends\utils.py", line 122, in execute
    return super().execute(sql, params)
  File "C:\Users\puttu\AppData\Roaming\Python\Python310\site-packages\django\db\backends\utils.py", line 79, in execute
    return self._execute_with_wrappers(
  File "C:\Users\puttu\AppData\Roaming\Python\Python310\site-packages\django\db\backends\utils.py", line 92, in _execute_with_wrappers
    return executor(sql, params, many, context)
  File "C:\Users\puttu\AppData\Roaming\Python\Python310\site-packages\django\db\backends\utils.py", line 100, in _execute
    with self.db.wrap_database_errors:
  File "C:\Users\puttu\AppData\Roaming\Python\Python310\site-packages\django\db\utils.py", line 91, in __exit__
    raise dj_exc_value.with_traceback(traceback) from exc_value
  File "C:\Users\puttu\AppData\Roaming\Python\Python310\site-packages\django\db\backends\utils.py", line 105, in _execute
    return self.cursor.execute(sql, params)
  File "C:\Users\puttu\AppData\Roaming\Python\Python310\site-packages\django\db\backends\mysql\base.py", line 76, in execute
    return self.cursor.execute(query, args)
  File "C:\Users\puttu\AppData\Roaming\Python\Python310\site-packages\pymysql\cursors.py", line 153, in execute
    result = self._query(query)
  File "C:\Users\puttu\AppData\Roaming\Python\Python310\site-packages\pymysql\cursors.py", line 322, in _query
    conn.query(q)
  File "C:\Users\puttu\AppData\Roaming\Python\Python310\site-packages\pymysql\connections.py", line 563, in query
    self._affected_rows = self._read_query_result(unbuffered=unbuffered)
  File "C:\Users\puttu\AppData\Roaming\Python\Python310\site-packages\pymysql\connections.py", line 825, in _read_query_result
    result.read()
  File "C:\Users\puttu\AppData\Roaming\Python\Python310\site-packages\pymysql\connections.py", line 1199, in read
    first_packet = self.connection._read_packet()
  File "C:\Users\puttu\AppData\Roaming\Python\Python310\site-packages\pymysql\connections.py", line 775, in _read_packet
    packet.raise_for_error()
  File "C:\Users\puttu\AppData\Roaming\Python\Python310\site-packages\pymysql\protocol.py", line 219, in raise_for_error
    err.raise_mysql_exception(self._data)
  File "C:\Users\puttu\AppData\Roaming\Python\Python310\site-packages\pymysql\err.py", line 150, in raise_mysql_exception
    raise errorclass(errno, errval)
django.db.utils.OperationalError: (1054, "Unknown column 'risk.RiskPriority' in 'field list'")
2025-06-02 10:15:32,463 - django.request - ERROR - Internal Server Error: /api/risks/
Traceback (most recent call last):
  File "C:\Users\puttu\AppData\Roaming\Python\Python310\site-packages\django\db\backends\utils.py", line 105, in _execute
    return self.cursor.execute(sql, params)
  File "C:\Users\puttu\AppData\Roaming\Python\Python310\site-packages\django\db\backends\mysql\base.py", line 76, in execute
    return self.cursor.execute(query, args)
  File "C:\Users\puttu\AppData\Roaming\Python\Python310\site-packages\pymysql\cursors.py", line 153, in execute
    result = self._query(query)
  File "C:\Users\puttu\AppData\Roaming\Python\Python310\site-packages\pymysql\cursors.py", line 322, in _query
    conn.query(q)
  File "C:\Users\puttu\AppData\Roaming\Python\Python310\site-packages\pymysql\connections.py", line 563, in query
    self._affected_rows = self._read_query_result(unbuffered=unbuffered)
  File "C:\Users\puttu\AppData\Roaming\Python\Python310\site-packages\pymysql\connections.py", line 825, in _read_query_result
    result.read()
  File "C:\Users\puttu\AppData\Roaming\Python\Python310\site-packages\pymysql\connections.py", line 1199, in read
    first_packet = self.connection._read_packet()
  File "C:\Users\puttu\AppData\Roaming\Python\Python310\site-packages\pymysql\connections.py", line 775, in _read_packet
    packet.raise_for_error()
  File "C:\Users\puttu\AppData\Roaming\Python\Python310\site-packages\pymysql\protocol.py", line 219, in raise_for_error
    err.raise_mysql_exception(self._data)
  File "C:\Users\puttu\AppData\Roaming\Python\Python310\site-packages\pymysql\err.py", line 150, in raise_mysql_exception
    raise errorclass(errno, errval)
pymysql.err.OperationalError: (1054, "Unknown column 'risk.RiskPriority' in 'field list'")

The above exception was the direct cause of the following exception:

Traceback (most recent call last):
  File "C:\Users\puttu\AppData\Roaming\Python\Python310\site-packages\django\core\handlers\exception.py", line 55, in inner
    response = get_response(request)
  File "C:\Users\puttu\AppData\Roaming\Python\Python310\site-packages\django\core\handlers\base.py", line 197, in _get_response
    response = wrapped_callback(request, *callback_args, **callback_kwargs)
  File "C:\Users\puttu\AppData\Roaming\Python\Python310\site-packages\django\views\decorators\csrf.py", line 65, in _view_wrapper
    return view_func(request, *args, **kwargs)
  File "C:\Users\puttu\AppData\Roaming\Python\Python310\site-packages\rest_framework\viewsets.py", line 125, in view
    return self.dispatch(request, *args, **kwargs)
  File "C:\Users\puttu\AppData\Roaming\Python\Python310\site-packages\rest_framework\views.py", line 515, in dispatch
    response = self.handle_exception(exc)
  File "C:\Users\puttu\AppData\Roaming\Python\Python310\site-packages\rest_framework\views.py", line 475, in handle_exception
    self.raise_uncaught_exception(exc)
  File "C:\Users\puttu\AppData\Roaming\Python\Python310\site-packages\rest_framework\views.py", line 486, in raise_uncaught_exception
    raise exc
  File "C:\Users\puttu\AppData\Roaming\Python\Python310\site-packages\rest_framework\views.py", line 512, in dispatch
    response = handler(request, *args, **kwargs)
  File "C:\Users\puttu\Music\GRC_INTEGRATIONS\GRC\GRC\backend\grc\views.py", line 1008, in list
    return super().list(request)
  File "C:\Users\puttu\AppData\Roaming\Python\Python310\site-packages\rest_framework\mixins.py", line 46, in list
    return Response(serializer.data)
  File "C:\Users\puttu\AppData\Roaming\Python\Python310\site-packages\rest_framework\serializers.py", line 797, in data
    ret = super().data
  File "C:\Users\puttu\AppData\Roaming\Python\Python310\site-packages\rest_framework\serializers.py", line 251, in data
    self._data = self.to_representation(self.instance)
  File "C:\Users\puttu\AppData\Roaming\Python\Python310\site-packages\rest_framework\serializers.py", line 715, in to_representation
    return [
  File "C:\Users\puttu\AppData\Roaming\Python\Python310\site-packages\django\db\models\query.py", line 400, in __iter__
    self._fetch_all()
  File "C:\Users\puttu\AppData\Roaming\Python\Python310\site-packages\django\db\models\query.py", line 1928, in _fetch_all
    self._result_cache = list(self._iterable_class(self))
  File "C:\Users\puttu\AppData\Roaming\Python\Python310\site-packages\django\db\models\query.py", line 91, in __iter__
    results = compiler.execute_sql(
  File "C:\Users\puttu\AppData\Roaming\Python\Python310\site-packages\django\db\models\sql\compiler.py", line 1574, in execute_sql
    cursor.execute(sql, params)
  File "C:\Users\puttu\AppData\Roaming\Python\Python310\site-packages\django\db\backends\utils.py", line 122, in execute
    return super().execute(sql, params)
  File "C:\Users\puttu\AppData\Roaming\Python\Python310\site-packages\django\db\backends\utils.py", line 79, in execute
    return self._execute_with_wrappers(
  File "C:\Users\puttu\AppData\Roaming\Python\Python310\site-packages\django\db\backends\utils.py", line 92, in _execute_with_wrappers
    return executor(sql, params, many, context)
  File "C:\Users\puttu\AppData\Roaming\Python\Python310\site-packages\django\db\backends\utils.py", line 100, in _execute
    with self.db.wrap_database_errors:
  File "C:\Users\puttu\AppData\Roaming\Python\Python310\site-packages\django\db\utils.py", line 91, in __exit__
    raise dj_exc_value.with_traceback(traceback) from exc_value
  File "C:\Users\puttu\AppData\Roaming\Python\Python310\site-packages\django\db\backends\utils.py", line 105, in _execute
    return self.cursor.execute(sql, params)
  File "C:\Users\puttu\AppData\Roaming\Python\Python310\site-packages\django\db\backends\mysql\base.py", line 76, in execute
    return self.cursor.execute(query, args)
  File "C:\Users\puttu\AppData\Roaming\Python\Python310\site-packages\pymysql\cursors.py", line 153, in execute
    result = self._query(query)
  File "C:\Users\puttu\AppData\Roaming\Python\Python310\site-packages\pymysql\cursors.py", line 322, in _query
    conn.query(q)
  File "C:\Users\puttu\AppData\Roaming\Python\Python310\site-packages\pymysql\connections.py", line 563, in query
    self._affected_rows = self._read_query_result(unbuffered=unbuffered)
  File "C:\Users\puttu\AppData\Roaming\Python\Python310\site-packages\pymysql\connections.py", line 825, in _read_query_result
    result.read()
  File "C:\Users\puttu\AppData\Roaming\Python\Python310\site-packages\pymysql\connections.py", line 1199, in read
    first_packet = self.connection._read_packet()
  File "C:\Users\puttu\AppData\Roaming\Python\Python310\site-packages\pymysql\connections.py", line 775, in _read_packet
    packet.raise_for_error()
  File "C:\Users\puttu\AppData\Roaming\Python\Python310\site-packages\pymysql\protocol.py", line 219, in raise_for_error
    err.raise_mysql_exception(self._data)
  File "C:\Users\puttu\AppData\Roaming\Python\Python310\site-packages\pymysql\err.py", line 150, in raise_mysql_exception
    raise errorclass(errno, errval)
django.db.utils.OperationalError: (1054, "Unknown column 'risk.RiskPriority' in 'field list'")
2025-06-02 10:15:38,756 - django.request - ERROR - Internal Server Error: /api/risks/
Traceback (most recent call last):
  File "C:\Users\puttu\AppData\Roaming\Python\Python310\site-packages\django\db\backends\utils.py", line 105, in _execute
    return self.cursor.execute(sql, params)
  File "C:\Users\puttu\AppData\Roaming\Python\Python310\site-packages\django\db\backends\mysql\base.py", line 76, in execute
    return self.cursor.execute(query, args)
  File "C:\Users\puttu\AppData\Roaming\Python\Python310\site-packages\pymysql\cursors.py", line 153, in execute
    result = self._query(query)
  File "C:\Users\puttu\AppData\Roaming\Python\Python310\site-packages\pymysql\cursors.py", line 322, in _query
    conn.query(q)
  File "C:\Users\puttu\AppData\Roaming\Python\Python310\site-packages\pymysql\connections.py", line 563, in query
    self._affected_rows = self._read_query_result(unbuffered=unbuffered)
  File "C:\Users\puttu\AppData\Roaming\Python\Python310\site-packages\pymysql\connections.py", line 825, in _read_query_result
    result.read()
  File "C:\Users\puttu\AppData\Roaming\Python\Python310\site-packages\pymysql\connections.py", line 1199, in read
    first_packet = self.connection._read_packet()
  File "C:\Users\puttu\AppData\Roaming\Python\Python310\site-packages\pymysql\connections.py", line 775, in _read_packet
    packet.raise_for_error()
  File "C:\Users\puttu\AppData\Roaming\Python\Python310\site-packages\pymysql\protocol.py", line 219, in raise_for_error
    err.raise_mysql_exception(self._data)
  File "C:\Users\puttu\AppData\Roaming\Python\Python310\site-packages\pymysql\err.py", line 150, in raise_mysql_exception
    raise errorclass(errno, errval)
pymysql.err.OperationalError: (1054, "Unknown column 'risk.RiskPriority' in 'field list'")

The above exception was the direct cause of the following exception:

Traceback (most recent call last):
  File "C:\Users\puttu\AppData\Roaming\Python\Python310\site-packages\django\core\handlers\exception.py", line 55, in inner
    response = get_response(request)
  File "C:\Users\puttu\AppData\Roaming\Python\Python310\site-packages\django\core\handlers\base.py", line 197, in _get_response
    response = wrapped_callback(request, *callback_args, **callback_kwargs)
  File "C:\Users\puttu\AppData\Roaming\Python\Python310\site-packages\django\views\decorators\csrf.py", line 65, in _view_wrapper
    return view_func(request, *args, **kwargs)
  File "C:\Users\puttu\AppData\Roaming\Python\Python310\site-packages\rest_framework\viewsets.py", line 125, in view
    return self.dispatch(request, *args, **kwargs)
  File "C:\Users\puttu\AppData\Roaming\Python\Python310\site-packages\rest_framework\views.py", line 515, in dispatch
    response = self.handle_exception(exc)
  File "C:\Users\puttu\AppData\Roaming\Python\Python310\site-packages\rest_framework\views.py", line 475, in handle_exception
    self.raise_uncaught_exception(exc)
  File "C:\Users\puttu\AppData\Roaming\Python\Python310\site-packages\rest_framework\views.py", line 486, in raise_uncaught_exception
    raise exc
  File "C:\Users\puttu\AppData\Roaming\Python\Python310\site-packages\rest_framework\views.py", line 512, in dispatch
    response = handler(request, *args, **kwargs)
  File "C:\Users\puttu\Music\GRC_INTEGRATIONS\GRC\GRC\backend\grc\views.py", line 1008, in list
    return super().list(request)
  File "C:\Users\puttu\AppData\Roaming\Python\Python310\site-packages\rest_framework\mixins.py", line 46, in list
    return Response(serializer.data)
  File "C:\Users\puttu\AppData\Roaming\Python\Python310\site-packages\rest_framework\serializers.py", line 797, in data
    ret = super().data
  File "C:\Users\puttu\AppData\Roaming\Python\Python310\site-packages\rest_framework\serializers.py", line 251, in data
    self._data = self.to_representation(self.instance)
  File "C:\Users\puttu\AppData\Roaming\Python\Python310\site-packages\rest_framework\serializers.py", line 715, in to_representation
    return [
  File "C:\Users\puttu\AppData\Roaming\Python\Python310\site-packages\django\db\models\query.py", line 400, in __iter__
    self._fetch_all()
  File "C:\Users\puttu\AppData\Roaming\Python\Python310\site-packages\django\db\models\query.py", line 1928, in _fetch_all
    self._result_cache = list(self._iterable_class(self))
  File "C:\Users\puttu\AppData\Roaming\Python\Python310\site-packages\django\db\models\query.py", line 91, in __iter__
    results = compiler.execute_sql(
  File "C:\Users\puttu\AppData\Roaming\Python\Python310\site-packages\django\db\models\sql\compiler.py", line 1574, in execute_sql
    cursor.execute(sql, params)
  File "C:\Users\puttu\AppData\Roaming\Python\Python310\site-packages\django\db\backends\utils.py", line 122, in execute
    return super().execute(sql, params)
  File "C:\Users\puttu\AppData\Roaming\Python\Python310\site-packages\django\db\backends\utils.py", line 79, in execute
    return self._execute_with_wrappers(
  File "C:\Users\puttu\AppData\Roaming\Python\Python310\site-packages\django\db\backends\utils.py", line 92, in _execute_with_wrappers
    return executor(sql, params, many, context)
  File "C:\Users\puttu\AppData\Roaming\Python\Python310\site-packages\django\db\backends\utils.py", line 100, in _execute
    with self.db.wrap_database_errors:
  File "C:\Users\puttu\AppData\Roaming\Python\Python310\site-packages\django\db\utils.py", line 91, in __exit__
    raise dj_exc_value.with_traceback(traceback) from exc_value
  File "C:\Users\puttu\AppData\Roaming\Python\Python310\site-packages\django\db\backends\utils.py", line 105, in _execute
    return self.cursor.execute(sql, params)
  File "C:\Users\puttu\AppData\Roaming\Python\Python310\site-packages\django\db\backends\mysql\base.py", line 76, in execute
    return self.cursor.execute(query, args)
  File "C:\Users\puttu\AppData\Roaming\Python\Python310\site-packages\pymysql\cursors.py", line 153, in execute
    result = self._query(query)
  File "C:\Users\puttu\AppData\Roaming\Python\Python310\site-packages\pymysql\cursors.py", line 322, in _query
    conn.query(q)
  File "C:\Users\puttu\AppData\Roaming\Python\Python310\site-packages\pymysql\connections.py", line 563, in query
    self._affected_rows = self._read_query_result(unbuffered=unbuffered)
  File "C:\Users\puttu\AppData\Roaming\Python\Python310\site-packages\pymysql\connections.py", line 825, in _read_query_result
    result.read()
  File "C:\Users\puttu\AppData\Roaming\Python\Python310\site-packages\pymysql\connections.py", line 1199, in read
    first_packet = self.connection._read_packet()
  File "C:\Users\puttu\AppData\Roaming\Python\Python310\site-packages\pymysql\connections.py", line 775, in _read_packet
    packet.raise_for_error()
  File "C:\Users\puttu\AppData\Roaming\Python\Python310\site-packages\pymysql\protocol.py", line 219, in raise_for_error
    err.raise_mysql_exception(self._data)
  File "C:\Users\puttu\AppData\Roaming\Python\Python310\site-packages\pymysql\err.py", line 150, in raise_mysql_exception
    raise errorclass(errno, errval)
django.db.utils.OperationalError: (1054, "Unknown column 'risk.RiskPriority' in 'field list'")
2025-06-02 10:18:47,618 - django.utils.autoreload - INFO - C:\Users\puttu\Music\GRC_INTEGRATIONS\GRC\GRC\backend\backend\settings.py changed, reloading.
